[34m[1mwandb[39m[22m: [32m[41mERROR[39m[49m Error while calling W&B API: failed to find run nyc_airbnb/2l7sl0xw (<Response [404]>)
[34m[1mwandb[39m[22m: [32m[41mERROR[39m[49m Permission denied to access zachpipher123/nyc_airbnb/2l7sl0xw
Traceback (most recent call last):
  File "/root/miniconda3/envs/mlflow-da93339ed90e31f137db8dabdae14e69a71f1301/lib/python3.9/site-packages/wandb/sdk/lib/retry.py", line 128, in __call__
    result = self._call_fn(*args, **kwargs)
  File "/root/miniconda3/envs/mlflow-da93339ed90e31f137db8dabdae14e69a71f1301/lib/python3.9/site-packages/wandb/sdk/internal/internal_api.py", line 241, in execute
    return self.client.execute(*args, **kwargs)  # type: ignore
  File "/root/miniconda3/envs/mlflow-da93339ed90e31f137db8dabdae14e69a71f1301/lib/python3.9/site-packages/wandb/vendor/gql-0.2.0/wandb_gql/client.py", line 52, in execute
    result = self._get_result(document, *args, **kwargs)
  File "/root/miniconda3/envs/mlflow-da93339ed90e31f137db8dabdae14e69a71f1301/lib/python3.9/site-packages/wandb/vendor/gql-0.2.0/wandb_gql/client.py", line 60, in _get_result
    return self.transport.execute(document, *args, **kwargs)
  File "/root/miniconda3/envs/mlflow-da93339ed90e31f137db8dabdae14e69a71f1301/lib/python3.9/site-packages/wandb/vendor/gql-0.2.0/wandb_gql/transport/requests.py", line 39, in execute
    request.raise_for_status()
  File "/root/miniconda3/envs/mlflow-da93339ed90e31f137db8dabdae14e69a71f1301/lib/python3.9/site-packages/requests/models.py", line 1021, in raise_for_status
    raise HTTPError(http_error_msg, response=self)
requests.exceptions.HTTPError: 404 Client Error: Not Found for url: https://api.wandb.ai/graphql
During handling of the above exception, another exception occurred:
Traceback (most recent call last):
  File "/root/Project-Build-an-ML-Pipeline-Starter/src/train_random_forest/run.py", line 303, in <module>
    go(args)
  File "/root/Project-Build-an-ML-Pipeline-Starter/src/train_random_forest/run.py", line 56, in go
    trainval_local_path = run.use_artifact(args.trainval_artifact).file()
  File "/root/miniconda3/envs/mlflow-da93339ed90e31f137db8dabdae14e69a71f1301/lib/python3.9/site-packages/wandb/sdk/wandb_run.py", line 333, in wrapper
    return func(self, *args, **kwargs)
  File "/root/miniconda3/envs/mlflow-da93339ed90e31f137db8dabdae14e69a71f1301/lib/python3.9/site-packages/wandb/sdk/wandb_run.py", line 2638, in use_artifact
    api.use_artifact(
  File "/root/miniconda3/envs/mlflow-da93339ed90e31f137db8dabdae14e69a71f1301/lib/python3.9/site-packages/wandb/apis/internal.py", line 129, in use_artifact
    return self.api.use_artifact(*args, **kwargs)
  File "/root/miniconda3/envs/mlflow-da93339ed90e31f137db8dabdae14e69a71f1301/lib/python3.9/site-packages/wandb/sdk/internal/internal_api.py", line 2573, in use_artifact
    response = self.gql(
  File "/root/miniconda3/envs/mlflow-da93339ed90e31f137db8dabdae14e69a71f1301/lib/python3.9/site-packages/wandb/sdk/internal/internal_api.py", line 213, in gql
    ret = self._retry_gql(
  File "/root/miniconda3/envs/mlflow-da93339ed90e31f137db8dabdae14e69a71f1301/lib/python3.9/site-packages/wandb/sdk/lib/retry.py", line 144, in __call__
    retry_timedelta_triggered = check_retry_fn(e)
  File "/root/miniconda3/envs/mlflow-da93339ed90e31f137db8dabdae14e69a71f1301/lib/python3.9/site-packages/wandb/util.py", line 1010, in no_retry_auth
    raise CommError(f"Permission denied to access {wandb.run.path}")
