2024-05-02 17:27:44,859 INFO    StreamThr :93225 [internal.py:wandb_internal():87] W&B internal server running at pid: 93225, started at: 2024-05-02 17:27:44.858547
2024-05-02 17:27:44,860 DEBUG   HandlerThread:93225 [handler.py:handle_request():144] handle_request: status
2024-05-02 17:27:44,862 INFO    WriterThread:93225 [datastore.py:open_for_write():85] open: /root/Project-Build-an-ML-Pipeline-Starter/src/data_check/wandb/run-20240502_172744-4ylu9rl0/run-4ylu9rl0.wandb
2024-05-02 17:27:44,864 DEBUG   SenderThread:93225 [sender.py:send():334] send: header
2024-05-02 17:27:44,869 DEBUG   SenderThread:93225 [sender.py:send():334] send: run
2024-05-02 17:27:44,871 INFO    SenderThread:93225 [sender.py:_maybe_setup_resume():721] checking resume status for None/nyc_airbnb/4ylu9rl0
2024-05-02 17:27:45,790 ERROR   SenderThread:93225 [internal_api.py:execute():244] 409 response executing GraphQL.
2024-05-02 17:27:45,790 ERROR   SenderThread:93225 [internal_api.py:execute():245] {"errors":[{"message":"run 4ylu9rl0 was previously created and deleted; try a new run name","path":["upsertBucket"]}],"data":{"upsertBucket":null}}
2024-05-02 17:27:47,219 ERROR   SenderThread:93225 [internal_api.py:execute():244] 409 response executing GraphQL.
2024-05-02 17:27:47,219 ERROR   SenderThread:93225 [internal_api.py:execute():245] {"errors":[{"message":"run 4ylu9rl0 was previously created and deleted; try a new run name","path":["upsertBucket"]}],"data":{"upsertBucket":null}}
2024-05-02 17:27:49,870 ERROR   SenderThread:93225 [internal_api.py:execute():244] 409 response executing GraphQL.
2024-05-02 17:27:49,870 ERROR   SenderThread:93225 [internal_api.py:execute():245] {"errors":[{"message":"run 4ylu9rl0 was previously created and deleted; try a new run name","path":["upsertBucket"]}],"data":{"upsertBucket":null}}
2024-05-02 17:27:49,870 INFO    SenderThread:93225 [retry.py:__call__():169] Retry attempt failed:
Traceback (most recent call last):
  File "/root/miniconda3/envs/mlflow-af6473294b18f57ea960125076520147a7a4be59/lib/python3.9/site-packages/wandb/sdk/lib/retry.py", line 128, in __call__
    result = self._call_fn(*args, **kwargs)
  File "/root/miniconda3/envs/mlflow-af6473294b18f57ea960125076520147a7a4be59/lib/python3.9/site-packages/wandb/sdk/internal/internal_api.py", line 241, in execute
    return self.client.execute(*args, **kwargs)  # type: ignore
  File "/root/miniconda3/envs/mlflow-af6473294b18f57ea960125076520147a7a4be59/lib/python3.9/site-packages/wandb/vendor/gql-0.2.0/wandb_gql/client.py", line 52, in execute
    result = self._get_result(document, *args, **kwargs)
  File "/root/miniconda3/envs/mlflow-af6473294b18f57ea960125076520147a7a4be59/lib/python3.9/site-packages/wandb/vendor/gql-0.2.0/wandb_gql/client.py", line 60, in _get_result
    return self.transport.execute(document, *args, **kwargs)
  File "/root/miniconda3/envs/mlflow-af6473294b18f57ea960125076520147a7a4be59/lib/python3.9/site-packages/wandb/vendor/gql-0.2.0/wandb_gql/transport/requests.py", line 39, in execute
    request.raise_for_status()
  File "/root/miniconda3/envs/mlflow-af6473294b18f57ea960125076520147a7a4be59/lib/python3.9/site-packages/requests/models.py", line 1021, in raise_for_status
    raise HTTPError(http_error_msg, response=self)
requests.exceptions.HTTPError: 409 Client Error: Conflict for url: https://api.wandb.ai/graphql
2024-05-02 17:27:49,871 DEBUG   HandlerThread:93225 [handler.py:handle_request():144] handle_request: keepalive
2024-05-02 17:27:54,662 ERROR   SenderThread:93225 [internal_api.py:execute():244] 409 response executing GraphQL.
2024-05-02 17:27:54,662 ERROR   SenderThread:93225 [internal_api.py:execute():245] {"errors":[{"message":"run 4ylu9rl0 was previously created and deleted; try a new run name","path":["upsertBucket"]}],"data":{"upsertBucket":null}}
2024-05-02 17:27:54,872 DEBUG   HandlerThread:93225 [handler.py:handle_request():144] handle_request: keepalive
2024-05-02 17:27:59,873 DEBUG   HandlerThread:93225 [handler.py:handle_request():144] handle_request: keepalive
2024-05-02 17:28:04,349 ERROR   SenderThread:93225 [internal_api.py:execute():244] 409 response executing GraphQL.
2024-05-02 17:28:04,349 ERROR   SenderThread:93225 [internal_api.py:execute():245] {"errors":[{"message":"run 4ylu9rl0 was previously created and deleted; try a new run name","path":["upsertBucket"]}],"data":{"upsertBucket":null}}
2024-05-02 17:28:04,874 DEBUG   HandlerThread:93225 [handler.py:handle_request():144] handle_request: keepalive
2024-05-02 17:28:09,875 DEBUG   HandlerThread:93225 [handler.py:handle_request():144] handle_request: keepalive
2024-05-02 17:28:14,877 DEBUG   HandlerThread:93225 [handler.py:handle_request():144] handle_request: keepalive
2024-05-02 17:28:19,878 DEBUG   HandlerThread:93225 [handler.py:handle_request():144] handle_request: keepalive
2024-05-02 17:28:22,713 ERROR   SenderThread:93225 [internal_api.py:execute():244] 409 response executing GraphQL.
2024-05-02 17:28:22,713 ERROR   SenderThread:93225 [internal_api.py:execute():245] {"errors":[{"message":"run 4ylu9rl0 was previously created and deleted; try a new run name","path":["upsertBucket"]}],"data":{"upsertBucket":null}}
2024-05-02 17:28:24,879 DEBUG   HandlerThread:93225 [handler.py:handle_request():144] handle_request: keepalive
2024-05-02 17:28:29,880 DEBUG   HandlerThread:93225 [handler.py:handle_request():144] handle_request: keepalive
2024-05-02 17:28:34,882 DEBUG   HandlerThread:93225 [handler.py:handle_request():144] handle_request: keepalive
2024-05-02 17:28:37,871 INFO    MainThread:93225 [internal.py:handle_exit():77] Internal process exited
